<?xml version="1.0"?>
<robot  xmlns:xacro="http://www.ros.org/wiki/xacro" name="firefighter" >
	
<xacro:property name="width" value=".2" />


  <link name="joint1">
    <inertial>
      <origin rpy="0.0 0 0" xyz="0 0 -1.5708"/>
      <mass value="0.33"/>
      <inertia ixx="0.000784" ixy="0.0" ixz="0.0" iyy="0.000867" iyz="0.0" izz="0.001598"/>
    </inertial>
    <visual>
      <geometry>
	     <!--- 0.0 0 -0.04  1.5708 3.14159-->
       <mesh filename="meshes/visual/joint1.obj"/>
      </geometry>
      <origin xyz = "0.0 0 0 " rpy = " 0 0 -1.5708"/>
    </visual>
    <collision>
      <geometry>
	     <!--- 0.0 0 -0.04  1.5708 3.14159-->
       <mesh filename="meshes/collision/joint1.obj"/>
        </geometry>
        <origin xyz = "0.0 0 0 " rpy = " 0 0 -1.5708"/>
    </collision>
  </link>

  <link name="joint2">
    <inertial>
      <origin xyz = "0.0 0 -0.06096 " rpy = " 0 0 -1.5708"/>
      <mass value="0.19"/>
      <inertia ixx="0.000148" ixy="0.0" ixz="0.0" iyy="0.000148" iyz="0.0" izz="9.6e-05"/>
    </inertial>
    <visual>
      <geometry>
       <mesh filename="meshes/visual/joint2.obj"/>
      </geometry>
      <origin xyz = "0.0 0 -0.06096 " rpy = " 0 0 -1.5708"/>
    </visual>
    <collision>
     <geometry>
       <mesh filename="meshes/collision/joint2.obj"/>
      </geometry>
      <origin xyz = "0.0 0 -0.06096 " rpy = " 0 0 -1.5708"/>
    </collision>
  </link>


  <link name="joint3">
    <inertial>
      <origin xyz = "0.0 0 0.03256 " rpy = " 0 -1.5708 0"/>
      <mass value="0.16"/>
      <inertia ixx="0.000148" ixy="0.0" ixz="0.0" iyy="0.000148" iyz="0.0" izz="9.6e-05"/>
    </inertial>
    <visual>
      <geometry>
       <mesh filename="meshes/visual/joint3.obj"/>
      </geometry>
      <origin xyz = "0.0 0 0.03256 " rpy = " 0 -1.5708 0"/>
    </visual>
    <collision>
      <geometry>
       <mesh filename="meshes/collision/joint3.obj"/>
      </geometry>
      <origin xyz = "0.0 0 0.03256 " rpy = " 0 -1.5708 0"/>
    </collision>
  </link>


  <link name="joint4">
    <inertial>
      <origin xyz = "0.0 0 0.03056 " rpy = " 0 -1.5708 0"/>
      <mass value="0.124"/>
      <inertia ixx="0.000103" ixy="0.0" ixz="0.0" iyy="0.000103" iyz="0.0" izz="9.6e-05"/>
    </inertial>
    <visual>
      <geometry>
       <!--- 0.0 0 -0.04 -->
       <mesh filename="meshes/visual/joint4.obj"/>
      </geometry>
      <origin xyz = "0.0 0 0.03056 " rpy = " 0 -1.5708 0"/>
    </visual>
    <collision>
      <geometry>
       <!--- 0.0 0 -0.04 -->
       <mesh filename="meshes/collision/joint4.obj"/>
      </geometry>
      <origin xyz = "0.0 0 0.03056 " rpy = " 0 -1.5708 0"/>
    </collision>
  </link>


  <link name="joint5">
    <inertial>
      <origin xyz = "0.0 0 -0.03356 " rpy = " -1.5708 0 0"/>
      <mass value="0.11"/>
      <inertia ixx="0.000103" ixy="0.0" ixz="0.0" iyy="0.000103" iyz="0.0" izz="9.6e-05"/>
    </inertial>
    <visual>
      <geometry>
       <!--- 0.0 0 -0.04 -->
       <mesh filename="meshes/visual/joint5.obj"/>
      </geometry>
    <origin xyz = "0.0 0 -0.03356 " rpy = " -1.5708 0 0"/>
    </visual>
    <collision>
       <geometry>
       <!--- 0.0 0 -0.04 -->
       <mesh filename="meshes/collision/joint5.obj"/>
      </geometry>
      <origin xyz = "0.0 0 -0.03356 " rpy = " -1.5708 0 0"/>
    </collision>
  </link>


  <link name="joint6">
    <inertial>
      <origin xyz = "0.0 0 -0.038 " rpy = " 0 0 0"/>
      <mass value="0.0739"/>
      <inertia ixx="6.649e-05" ixy="0.0" ixz="0.0" iyy="6.649e-05" iyz="0.0" izz="9.6e-05"/>
    </inertial>
    <visual>
      <geometry>
       <!--- 0.0 0 -0.04 -->
       <mesh filename="meshes/visual/joint6.obj"/>
      </geometry>
      <origin xyz = "0 0.00 -0.038 " rpy = " 0 0 0"/>
    </visual>
    <collision>
      <geometry>
       <!--- 0.0 0 -0.04 -->
       <mesh filename="meshes/collision/joint6.obj"/>
      </geometry>
      <origin xyz = "0 0.00 -0.038 " rpy = " 0 0 0"/>
    </collision>
  </link>


  <link name="joint6_flange">
    <inertial>
      <origin xyz = "0.0 0 -0.012 " rpy = " 0 0 0"/>
      <mass value="0.035"/>
      <inertia ixx="1.49e-05" ixy="0.0" ixz="0.0" iyy="1.49e-05" iyz="0.0" izz="1.96e-05"/>
    </inertial>
    <visual>
      <geometry>
       <!--- 0.0 0 -0.04 -->
       <mesh filename="meshes/visual/joint7.obj"/>
      </geometry>
    <origin xyz = "0.0 0 -0.012 " rpy = " 0 0 0"/>
    </visual>
    <collision>
      <geometry>
       <!--- 0.0 0 -0.04 -->
       <mesh filename="meshes/collision/joint7.obj"/>
      </geometry>
    <origin xyz = "0.0 0 -0.012 " rpy = " 0 0 0"/>
    </collision>
  </link>





  <joint name="joint2_to_joint1" type="revolute">
    <axis xyz="0 0 1"/>
    <limit effort = "1000.0" lower = "-3.14" upper = "3.14159" velocity = "0"/>
    <parent link="joint1"/>
    <child link="joint2"/>
    <origin xyz= "0 0 0.13156" rpy = "0 0 0"/>  
  </joint>


  <joint name="joint3_to_joint2" type="revolute">
    <axis xyz="0 0 1"/>
    <limit effort = "1000.0" lower = "-3.14" upper = "3.14159" velocity = "0"/>
    <parent link="joint2"/>
    <child link="joint3"/>
    <origin xyz= "0 0  0" rpy = "0 1.5708 -1.5708"/>  
  </joint>


  <joint name="joint4_to_joint3" type="revolute">
    <axis xyz=" 0 0 1"/>
    <limit effort = "1000.0" lower = "-3.14" upper = "3.14159" velocity = "0"/>
    <parent link="joint3"/>
    <child link="joint4"/>
    <origin xyz= "  -0.1104 0 0   " rpy = "0 0 0"/>  
  </joint>



  <joint name="joint5_to_joint4" type="revolute">
    <axis xyz=" 0 0 1"/>
    <limit effort = "1000.0" lower = "-3.14" upper = "3.14159" velocity = "0"/>
    <parent link="joint4"/>
    <child link="joint5"/>
    <origin xyz= "-0.096 0 0.06462" rpy = "0 0 -1.5708"/>  
  </joint>

  <joint name="joint6_to_joint5" type="revolute">
    <axis xyz="0 0 1"/>
    <limit effort = "1000.0" lower = "-3.14" upper = "3.14159" velocity = "0"/>
    <parent link="joint5"/>
    <child link="joint6"/>
    <origin xyz= "0 -0.07318 0" rpy = "1.5708 -1.5708 0"/>  
  </joint>

  <joint name="joint6output_to_joint6" type="revolute">
    <axis xyz="0 0 1"/>
    <limit effort = "1000.0" lower = "-3.14" upper = "3.14159" velocity = "0"/>
    <parent link="joint6"/>
    <child link="joint6_flange"/>
    <origin xyz= "0 0.0456 0" rpy = "-1.5708 0 0"/>  
  </joint>

  <link name="gripper_base">
    <inertial>
      <origin rpy="0 0 0" xyz="0.0 0 -0.012" />
      <mass value="0.05" /> 
      <inertia ixx="1.0e-5" ixy="0.0" ixz="0.0" iyy="1.0e-5" iyz="0.0" izz="1.0e-5" />
    </inertial>
    <visual>
      <geometry>
       <mesh filename="mycobot_adaptive_gripper/gripper_base.dae"/>
      </geometry>
    <origin xyz = "0.0 0 -0.012 " rpy = " 0 0 0"/>
    </visual>
    <collision>
      <geometry>
       <mesh filename="mycobot_adaptive_gripper/gripper_base.dae"/>
      </geometry>
    <origin xyz = "0.0 0 -0.012 " rpy = " 0 0 0"/>
    </collision>
  </link>

  <link name="gripper_left1">
    <inertial>
      <origin rpy="0 0 0" xyz="0.039 -0.0133 -0.012" />
      <mass value="0.01" /> 
      <inertia ixx="1.0e-6" ixy="0.0" ixz="0.0" iyy="1.0e-6" iyz="0.0" izz="1.0e-6" />
    </inertial>
    <visual>
      <geometry>
       <mesh filename="mycobot_adaptive_gripper/gripper_left1.dae"/>
      </geometry>
    <origin xyz = "0.039 -0.0133 -0.012 " rpy = " 0 0 0"/>
    </visual>
    <collision>
      <geometry>
       <mesh filename="mycobot_adaptive_gripper/gripper_left1.dae"/>
      </geometry>
      <origin xyz = "0.039 -0.0133 -0.012 " rpy = " 0 0 0"/>
    </collision>
  </link>

  <link name="gripper_left2">
    <inertial>
      <origin rpy="0 0 0" xyz="0.005 -0.0195 -0.012" />
      <mass value="0.01" /> 
      <inertia ixx="1.0e-6" ixy="0.0" ixz="0.0" iyy="1.0e-6" iyz="0.0" izz="1.0e-6" />
    </inertial>
    <visual>
      <geometry>
       <mesh filename="mycobot_adaptive_gripper/gripper_left2.dae"/>
      </geometry>
    <origin xyz = "0.005 -0.0195 -0.012 " rpy = " 0 0 0"/>
    </visual>
    <collision>
      <geometry>
       <mesh filename="mycobot_adaptive_gripper/gripper_left2.dae"/>
      </geometry>
        <origin xyz = "0.005 -0.0195 -0.012 " rpy = " 0 0 0"/>
    </collision>
  </link>

  <link name="gripper_left3">
    <inertial>
      <origin rpy="0 0 0" xyz="0.012 0.0025 -0.012" />
      <mass value="0.01" /> 
      <inertia ixx="1.0e-6" ixy="0.0" ixz="0.0" iyy="1.0e-6" iyz="0.0" izz="1.0e-6" />
    </inertial>
    <visual>
      <geometry>
       <mesh filename="mycobot_adaptive_gripper/gripper_left3.dae"/>
      </geometry>
    <origin xyz = "0.012 0.0025 -0.012 " rpy = " 0 0 0"/>
    </visual>
    <collision>
      <geometry>
       <mesh filename="mycobot_adaptive_gripper/gripper_left3.dae"/>
      </geometry>
    <origin xyz = "0.012 0.0025 -0.012 " rpy = " 0 0 0"/>
    </collision>
  </link>

  <link name="gripper_right1">
    <inertial>
      <origin rpy="0 0 0" xyz="-0.039 -0.0133 -0.012" />
      <mass value="0.01" /> 
      <inertia ixx="1.0e-6" ixy="0.0" ixz="0.0" iyy="1.0e-6" iyz="0.0" izz="1.0e-6" />
    </inertial>
    <visual>
      <geometry>
       <mesh filename="mycobot_adaptive_gripper/gripper_right1.dae"/>
      </geometry>
    <origin xyz = "-0.039 -0.0133 -0.012 " rpy = " 0 0 0"/>
    </visual>
    <collision>
      <geometry>
       <mesh filename="mycobot_adaptive_gripper/gripper_right1.dae"/>
      </geometry>
        <origin xyz = "-0.039 -0.0133 -0.012 " rpy = " 0 0 0"/>
    </collision>
  </link>

  <link name="gripper_right2">
    <inertial>
      <origin rpy="0 0 0" xyz="-0.005 -0.0195 -0.012" />
      <mass value="0.01" /> 
      <inertia ixx="1.0e-6" ixy="0.0" ixz="0.0" iyy="1.0e-6" iyz="0.0" izz="1.0e-6" />
    </inertial>
    <visual>
      <geometry>
       <mesh filename="mycobot_adaptive_gripper/gripper_right2.dae"/>
      </geometry>
    <origin xyz = "-0.005 -0.0195 -0.012 " rpy = " 0 0 0"/>
    </visual>
    <collision>
      <geometry>
       <mesh filename="mycobot_adaptive_gripper/gripper_right2.dae"/>
      </geometry>
        <origin xyz = "-0.005 -0.0195 -0.012 " rpy = " 0 0 0"/>
    </collision>
  </link>

  <link name="gripper_right3">
    <inertial>
      <origin rpy="0 0 0" xyz="-0.012 0.0025 -0.012" />
      <mass value="0.01" /> 
      <inertia ixx="1.0e-6" ixy="0.0" ixz="0.0" iyy="1.0e-6" iyz="0.0" izz="1.0e-6" />
    </inertial>
    <visual>
      <geometry>
       <mesh filename="mycobot_adaptive_gripper/gripper_right3.dae"/>
      </geometry>
    <origin xyz = "-0.012 0.0025 -0.012 " rpy = " 0 0 0"/>
    </visual>
    <collision>
      <geometry>
       <mesh filename="mycobot_adaptive_gripper/gripper_right3.dae"/>
      </geometry>
    <origin xyz = "-0.012 0.0025 -0.012" rpy = " 0 0 0"/>
    </collision>
  </link>

<joint name="gripper_to_flange_joint" type="fixed">
  <parent link="joint6_flange"/>
  <child link="gripper_base"/>
  <origin xyz="0 0 0" rpy="0 0 0" /> 
</joint>

<joint name="gripper_controller" type="revolute">
    <axis xyz="0 0 1"/>
    <limit effort = "1000.0" lower = "-0.74" upper = "0.15" velocity = "0"/>
    <parent link="gripper_base"/>
    <child link="gripper_left3"/>
    <origin xyz= "-0.012 0.005 0" rpy = "0 0 0"/> 
  </joint>

  <joint name="gripper_base_to_gripper_left2" type="revolute">
    <axis xyz="0 0 1"/>
    <limit effort = "1000.0" lower = "-0.8" upper = "0.5" velocity = "0"/>
    <parent link="gripper_base"/>
    <child link="gripper_left2"/>
    <origin xyz= "-0.005 0.027 0" rpy = "0 0 0"/> 
    <mimic joint="gripper_controller" multiplier="1.0" offset="0" />
  </joint>

  <joint name="gripper_left3_to_gripper_left1" type="revolute">
    <axis xyz="0 0 1"/>
    <limit effort = "1000.0" lower = "-0.5" upper = "0.5" velocity = "0"/>
    <parent link="gripper_left3"/>
    <child link="gripper_left1"/>
    <origin xyz= "-0.027 0.016 0" rpy = "0 0 0"/> 
    <mimic joint="gripper_controller" multiplier="-1.0" offset="0" />
  </joint>

  <joint name="gripper_base_to_gripper_right3" type="revolute">
    <axis xyz="0 0 1"/>
    <limit effort = "1000.0" lower = "-0.15" upper = "0.7" velocity = "0"/>
    <parent link="gripper_base"/>
    <child link="gripper_right3"/>
    <origin xyz= "0.012 0.005 0" rpy = "0 0 0"/> 
    <mimic joint="gripper_controller" multiplier="-1.0" offset="0" />
  </joint>

  <joint name="gripper_base_to_gripper_right2" type="revolute">
    <axis xyz="0 0 1"/>
    <limit effort = "1000.0" lower = "-0.5" upper = "0.8" velocity = "0"/>
    <parent link="gripper_base"/>
    <child link="gripper_right2"/>
    <origin xyz= "0.005 0.027 0" rpy = "0 0 0"/> 
    <mimic joint="gripper_controller" multiplier="-1.0" offset="0" />
  </joint>

  <joint name="gripper_right3_to_gripper_right1" type="revolute">
    <axis xyz="0 0 1"/>
    <limit effort = "1000.0" lower = "-0.5" upper = "0.5" velocity = "0"/>
    <parent link="gripper_right3"/>
    <child link="gripper_right1"/>
    <origin xyz= "0.027 0.016 0" rpy = "0 0 0"/> 
    <mimic joint="gripper_controller" multiplier="1.0" offset="0" />
  </joint>

</robot>

